# 7.3 API 에러 핸들링

코드에서 발생할 수 있는 에러 상황에 대해 명시적인 코드를 작성하면 유지보수가 용이해지고 사용자에게도 구체적인 에러 상황을 전달할 수 있다. 이번 챕터에서는 비동기 API 에러를 구체적이고 명시적으로 핸들링하는 방법을 다룬다.

## **타입 가드 활용하기**

Axios 라이브러리에는 Axios 에러에 대하 isAxiosError라는 타입 가드를 제공한다. 이 타입 가드를 직접 사용할 수도 있지만 서버 에러임을 명확히 표시하고 서버로부터 받는 에러 응답 객체를 구체적으로 정의하여 에러 객체의 속성을 파악할 수 있다.

```tsx
interface ErrorResponse {
  status: string;
  serverDateTime: string;
  errorCode: string;
  errorMessage: string;
}
```

ErrorResponse 인터페이스를 사용하여 처리해야 할 Axios 에러 형태는 `AxiosError<ErrorResponse>`로 표현할 수 있으며 다음과 같이 타입 가드를 명시적으로 작성할 수 있다.

```tsx
// axios.isAxiosError(error)반환 값이 true면 error는 AxiosError<ErrorResponse>타입이 된다. (타입명제)
function isServerError(error: unknown): error is AxiosError<ErrorResponse> {
  return axios.isAxiosError(error);
}
```

> 사용자 정의 타입 가드를 정의할 때는 타입 가드 함수의 반한 타입으로 `parameterName is Type` 형태의 타입 명제를 정의해 주는 것이 좋다. 이때 parameterName은 타입 가드 함수의 시그니처에 포함된 매개변수여야 한다.

아래와 같이 타입 가드를 활용하면 서버 에러를 명시적으로 확인 가능하다.

```tsx
const onClickDeleteHistoryButton = async (id: string) => {
  try {
    await axios.post("https://....", { id });

    alert("주문 내역이 삭제되었습니다.");
  } catch (error: unknown) {
    if (isServerError(e) && e.response && e.response.data.errorMessage) {
      // 서버 에러일 때의 처리임을 명시적으로 알 수 있다 setErrorMessage(e.response.data.errorMessage);
      return;
    }
    setErrorMessage("일시적인 에러가 발생했습니다. 잠시 후 다시 시도해주세요");
  }
};
```

<br>

## **에러 서브클래싱하기**

실제 요청을 처리할 때 단순한 서버 에러도 발생하지만 인증 정보 에러, 네트워크 에러, 타임아웃 에러와 같은 다양한 에러가 발생하기도 한다. 이를 더욱 명시적으로 표시하기 위해 서브클래싱(Subclassing)을 활용할 수 있다.

> **서브클래싱(Subclassing)**
>
> 기존(상위 또는 부모) 클래스를 확장하여 새로운(하위 또는 자식) 클래스를 만드는 과정을 말하며, 새로운 클래스는 상위 클래스의 모든 속성과 메서드를 상속받아 사용할 수 있고 추가적인 속성과 메서드를 정의할 수도 있다.

사용자에게 주문 내역을 보여주기 위해 서버에 주문 내역을 요청하는 코드 예시는 다음과 같다.

```tsx
const getOrderHistory = async (page: number): Promise<History> => {
  try {
    const { data } = await axios.get(`https://some.site?page=${page}`);
    const history = await JSON.parse(data);

    return history;
  } catch (error) {
    alert(error.message);
  }
};
```

이 코드는 에러가 발생시 에러 메세지를 alert을 사용해 사용자에게 표시한다. 이때 서버에서 전달된 에러메세지를 사용하기 때문에 사용자는 어떤 에러인지 판단할 수 있더라도, 개발자 입장에서는 어떤 에러가 발생한 것인지 판단할 수 없다.

이때 서브클래싱을 활용하면 에러가 발생했을 때 코드상에서 어떤 에러인지를 바로 확인할 수 있고, 에러 인스턴스에 따라 에러 처리 방식을 다르게 구현할 수 있다.

```tsx
class OrderHttpError extends Error {
  private readonly privateResponse: AxiosResponse<ErrorResponse> | undefined;

  constructor(message?: string, response?: AxiosResponse<ErrorResponse>) {
    super(message);
    this.name = "OrderHttpError";
    this.privateResponse = response;
  }

  get response(): AxiosResponse<ErrorResponse> | undefined {
    return this.privateResponse;
  }
}

class NetworkError extends Error {
  constructor(message = "") {
    super(message);
    this.name = "NetworkError";
  }
}

class UnauthorizedError extends Error {
  constructor(message: string, response?: AxiosResponse<ErrorResponse>) {
    super(message, response);
    this.name = "UnauthorizedError";
  }
}
```

이후 아래와 같이 에러 객체를 상속한 OrderHttpError, NetworkError, UnauthorizedError를 정의한다. Axios를 사용하고 있다면 조건에 따라 인터셉터에서 적합한 에러 객체를 전달할 수 있다.

```tsx
const httpErrorHandler = (
  error: AxiosError<ErrorResponse> | Error
): Promise<Error> => {
  let promiseError: Promise<Error>;

  if (axios.isAxiosError(error)) {
    if (Object.is(error.code, "ECONNABORTED")) {
      promiseError = Promise.reject(new TimeoutError());
    } else if (Object.is(error.message, "Network Error")) {
      promiseError = Promise.reject(new NetworkError());
    } else {
      const { response } = error as AxiosError<ErrorResponse>;
      switch (response?.status) {
        case HttpStatusCode.UNAUTHORIZED:
          promiseError = Promise.reject(
            new UnauthorizedError(response?.data.message, response)
          );
          break;
        default:
          promiseError = Promise.reject(
            new OrderHttpError(response?.data.message, response)
          );
      }
    }
  } else {
    promiseError = Promise.reject(error);
  }

  return promiseError;
};
```

이는 요청 코드에서 다음과 같이 사용할 수 있다.

```tsx
const alert = (meesage: string, { onClose }: { onClose?: () => void }) => {};

const onActionError = (
  error: unknown,
  params?: Omit<AlertPopup, "type" | "message">
) => {
  if (error instanceof UnauthorizedError) {
    onUnauthorizedError(
      error.message,
      errorCallback?.onUnauthorizedErrorCallback
    );
  } else if (error instanceof NetworkError) {
    alert("네트워크 연결이 원활하지 않습니다. 잠시 후 다시 시도해주세요.", {
      onClose: errorCallback?.onNetworkErrorCallback,
    });
  } else if (error instanceof OrderHttpError) {
    alert(error.message, params);
  } else if (error instanceof Error) {
    alert(error.message, params);
  } else {
    alert(defaultHttpErrorMessage, params);
  }

  const getOrderHistory = async (page: number): Promise<History> => {
    try {
      const { data } = await fetchOrderHistory({ page });
      const history = await JSON.parse(data);

      return history;
    } catch (error) {
      onActionError(error);
    }
  };
};
```

> **Omit**
>
> [Omit](https://www.typescriptlang.org/docs/handbook/utility-types.html#omittype-keys) 은 객체 타입 (interface 등)에서 string literal 혹은 union of string으로 받은 keys를 제외한 타입을 생성하는 유틸리티 타입으로 Pick과는 반대이다.

이처럼 에러를 서브클래싱하여 표현하면 명시적으로 에러를 처리할 수 있다. `error instanceof OrderHttpError`와 같이 작성된 타입 가드문을 통해 코드상에서 에러 핸들링에 대한 부분을 한눈에 볼 수 있다.

<br>

## **인터셉터를 활용한 에러 처리**

Axios와 같은 페칭 라이브러리는 [인터셉터(interceptors)](https://axios-http.com/docs/interceptors)기능을 제공한다. 이를 사용하면 HTTP 에러에 일관된 로직을 적용할 수 있다.

```tsx
const httpErrorHandler = (
  error: AxiosError<ErrorResponse> | Error
): Promise<Error> => {
  (error) => {
    // 401 에러인 경우 로그인 페이지로 이동
    if (error.response && error.response.status === 401) {
      window.location.href = `${backOfficeAuthHost}/login?targetUrl=${window.location.href}`;
    }
    return Promise.reject(error);
  };
};

// 응답 인터셉트 추가
orderApiRequester.interceptors.response.use(
  (response: AxiosResponse) => response,
  httpErrorHandler // 2xx 외의 범위에 있는 상태코드는 이 함수를 트리거
);
```

<br>

## **에러 바운더리를 활용한 에러 처리**

에러 바운더리는 리액트 컴포넌트 트리에서 에러가 발생할 때 공통으로 에러를 처리하는 리액트 컴포넌트이다. 에러 바운더리를 사용하면 리액트 컴포넌트 트리 하위에 있는 컴포넌트에서 발생한 에러를 캐치하고, 해당 에러를 가장 가까운 부모 에러 바운더리에서 처리하게 할 수 있습니다.

> **에러 바운더리(Error Boundary)**
>
> [에러 경계](https://ko.legacy.reactjs.org/docs/error-boundaries.html)는 하위 컴포넌트 트리의 어디에서든 자바스크립트 에러를 기록하며 깨진 컴포넌트 트리 대신 폴백 UI를 보여주는 React 컴포넌트입니다. 에러 경계는 렌더링 도중 생명주기 메서드 및 그 아래에 있는 전체 트리에서 에러를 잡아냅니다.

```tsx
import React, { ErrorInfo } from "react";
import ErrorPage from "pages/ErrorPage";

interface ErrorBoundaryProps {}

interface ErrorBoundaryState {
  hasError: boolean;
}

class ErrorBoundary extends React.Component<
  ErrorBoundaryProps,
  ErrorBoundaryState
> {
  constructor(props: ErrorBoundaryProps) {
    super(props);
    this.state = { hasError: false };
  }

  static getDerivedStateFromError(): ErrorBoundaryState {
    return { hasError: true };
  }

  componentDidCatch(error: Error, errorInfo: ErrorInfo): void {
    this.setState({ hasError: true });

    console.error(error, errorInfo);
  }

  render(): React.ReactNode {
    const { children } = this.props;
    const { hasError } = this.state;

    return hasError ? <ErrorPage /> : children;
  }
}

const App = () => {
  return (
    <ErrorBoundary>
      <OrderHistoryPage />
    </ErrorBoundary>
  );
};
```

이러첨 작성하면 OrderHistoryPage 컴포넌트 내에서 처리되지 않은 에러가 있을 때 에러 바운더리에서 에러 페이지를 노출한다. 이외에도 에러 바운더리에 로그를 보내는 코드를 추가하여 예상치 못한 에러의 발생 여부의 추적이 가능하다.

<br>

## **상태 관리 라이브러리에서의 에러 처리**

앞서 잠깐 살펴보았던 Redux의 에러 처리 방법은 다음과 같다.

```tsx
// API 호출에 관한 api call reducer
const apiCallSlice = createSlice({
  name: "apiCall",
  initialState,
  reducers: {
    setApiCall: (state, { payload: { status, urlInfo } }) => {
      /* API State를 채우는 logic */
    },
    setApiCallError: (state, { payload }: PayloadAction<any>) => {
      state.error = payload;
    },
  },
});

const API = axios.create();

const setAxiosInterceptor = (store: EnhancedStore) => {
  /* 중복 코드 생략 */
  // onSuccess시 처리를 인터셉터로 처리한다
  API.interceptors.response.use(
    (response: AxiosResponse) => {
      const { method, url } = response.config;

      store.dispatch(
        setApiCall({
          status: ApiCallStatus.None, // API 호출 상태를 `요청되지 않음`으로 변경
          urlInfo: { url, method },
        })
      );

      return response?.data?.data || response?.data;
    },
    (error: AxiosError) => {
      // 401 unauthorized
      if (error.response?.status === 401) {
        window.location.href = error.response.headers.location;

        return;
      }
      // 403 forbidden
      else if (error.response?.status === 403) {
        window.location.href = error.response.headers.location;
        return;
      }
      // 그 외에는 화면에 alert 띄우기
      else {
        message.error(`[서버 요청 에러]: ${error?.response?.data?.message}`);
      }

      const {
        config: { url, method },
      } = error;

      store.dispatch(
        setApiCall({
          status: ApiCallStatus.None, // API 호출 상태를 `요청되지 않음`으로 변경
          urlInfo: { url, method },
        })
      );

      return Promise.reject(error);
    }
  );
};
```

에러 상태를 관리하지 않고 처리할 수 있다면(e.g. 401, 403) 바로 처리하고, 그렇지 않다면 reject로 넘겨준다. 이후 액션을 정의하며 setApiCallError를 사용해 에러를 상태로 처리한다.

```tsx
const fetchMenu = createAsyncThunk(
  FETCH_MENU_REQUEST, // 액션 타입을 정의
  async ({ shopId, menuId }: FetchMenu) => {
    try {
      const data = await api.fetchMenu(shopId, menuId);
      return data; // 비동기 작업의 결과를 반환
    } catch (error) {
      setApiCallError({ error }); // setApiCallError로 에러를 상태로 처리
    }
  }
);
```

> **createAsyncThunk**
>
> `createAsyncThunk`는 Redux Toolkit 라이브러리의 한 기능으로, 비동기 로직을 쉽게 처리할 수 있게 해주는 함수입니다. 이 함수를 사용하면 비동기 작업을 수행하는 Thunk를 생성할 수 있습니다.
>
> 위에서 `fetchUserData`는 Thunk 함수로 변환되며, 이 함수는 비동기 API 요청을 수행하고, 요청이 성공하거나 실패할 때 자동으로 생성된 액션을 디스패치합니다.

이렇게 저장된 에러는 컴포넌트에서 사용할 수 있다. 만약 MobX를 사용하고 있다면 주로 스토어에서 에러 핸들링을 하며, 외부에서는 별도로 성공, 실패 등에 대해 참조하지 않고 비동기 동작의 수행 및 결괏값을 사용한다.

```tsx
class JobStore {
  jobs: Job[] = [];
  state: LoadingState = "PENDING"; // "PENDING" | "DONE" | "ERROR"; errorMsg = "";

  constructor() {
    makeAutoObservable(this);
  }

  async fetchJobList() {
    this.jobs = [];
    this.state = "PENDING";
    this.errorMsg = "";

    try {
      const projects = await fetchJobList();

      runInAction(() => {
        this.projects = projects;
        this.state = "DONE";
      });
    } catch (e) {
      runInAction(() => {
        // 에러 핸들링 코드를 작성
        this.state = "ERROR";
        this.errorMsg = e.message;
        showAlert();
      });
    }
  }

  get isLoading(): boolean {
    return state === "PENDING";
  }
}

const JobList = (): JSX.Element => {
  const [jobStore] = useState(() => new JobStore());

  if (jobStore.job.isLoading) {
    return <Loader />;
  }

  return (
    <>
      {jobStore.jobs.map((job) => (
        <Item job={job} />
      ))}
    </>
  );
};
```

<br>

## **react-query를 활용한 에러 처리**

react-query나 swr과 같은 데이터 패칭 라이브러리를 사용하면 요청에 대한 상태를 반환해주기 때문에 요청 상태를 확인하기 쉽다.

```tsx
const JobComponent: React.FC = () => {
  const { isError, error, isLoading, data } = useFetchJobList();
  if (isError) {
    return (
      <div>{`${error.message}가 발생했습니다. 나중에 다시 시도해주세요.`}</div>
    );
  }
  if (isLoading) {
    return <div>로딩 중입니다.</div>;
  }
  return (
    <>
      {data.map((job) => (
        <JobItem key={job.id} job={job} />
      ))}
    </>
  );
};
```

<br>

## **그 밖의 에러 처리**

API 응답은 주로 성공 시 2xx 코드를, 실패시 4xx, 5xx 코드를 반환한다. 일반적으로 API 요청 라이브러리에서도 HTTP 상태 코드에 따라 성공 응답인지 실패 응답인지를 판단한다.

그러나 비즈니스 로직에서의 유효성 검증에 의해 추가된 커스텀 에러는 200 응답과 함께 응답 바디에 별도의 상태 코드를 전달하기도 한다.

이 경우 커스텀 에러를 어떻게 구현하고 처리할지에 대한 논의가 이루어질 수 있지만, 이미 설계가 끝났거나 혹은 레거시로 남아있지만 범위가 넓어 대응이 어려울 경우 2xx번대의 성공 응답에 대한 커스텀 에러 처리를 구현해야 할 수도 있다.

예를 들어 아래와 같은 커스텀 에러를 반환한다고 가정하자

> httpStatus: 200 <br>
> { <br>
> "status": "C20005", // 성공인 경우 "SUCCESS"를 응답 <br>
> "message": "장바구니에 품절된 메뉴가 있습니다." <br>
> }

이 에러를 처리하기 위해 요청 함수 내에서 조건문으로 상태 비교가 가능하다

```tsx
const successHandler = (response: CreateOrderResponse) => {
  if (response.status === "SUCCESS") {
    // 성공 시 진행할 로직을 추가한다
    return;
  }
  throw new CustomError(response.status, response.message);
};
const createOrder = (data: CreateOrderData) => {
  try {
    const response = apiRequester.post("https://...", data);

    successHandler(response);
  } catch (error) {
    errorHandler(error);
  }
};
```

이 방법을 사용하면 간단하게 커스텀 에러를 처리할 수 있으며 영향 범위가 각 요청에 대해한 성공/실패 응답 처리 함수로 한정되어 관리하기 편하다.

하지만 이렇게 처리해야하는 API가 많을 경우 매번 조건문을 추가해야한다. 이때 커스텀 에러를 사용하고 있는 요청을 일괄적으로 에러로 처리하고 싶다면 Axios 등의 라이브러리 기능을 활용할 수 있다.

다음과 같이 특정 호스트에 대한 API requestor를 별도로 선언하고 상태 코드 비교 로직을 인터셉터에 추가할 수 있다.

```tsx
export const apiRequester: AxiosInstance = axios.create({
  baseURL: orderApiBaseUrl,
  ...defaultConfig,
});

export const httpSuccessHandler = (response: AxiosResponse) => {
  if (response.data.status !== "SUCCESS") {
    throw new CustomError(response?.data.message, response);
  }

  return response;
};

apiRequester.interceptors.response.use(httpSuccessHandler, httpErrorHandler);

const createOrder = (data: CreateOrderData) => {
  try {
    const response = apiRequester.post("https://...", data);

    successHandler(response);
  } catch (error) {
    // status가 SUCCESS가 아닌 경우 에러로 전달된다
    errorHandler(error);
  }
};
```
